Workbook

Sheet FormulaPolicy
A1: Case | B1: Expression | C1: Value
A2: Unsupported function | B2: VLOOKUP(1,A1:B3,2,FALSE) | C2: =VLOOKUP(1,A1:B3,2,FALSE)
A3: Cross-sheet reference | B3: Sheet2!A1 | C3: =Sheet2!A1
A4: Volatile function | B4: TODAY() | C4: =TODAY()
A5: Array-like range arithmetic | B5: A1:A3+B1:B3 | C5: =A1:A3+B1:B3
A6: Unsupported function | B6: VLOOKUP(1,A1:B3,2,FALSE) | C6: =VLOOKUP(1,A1:B3,2,FALSE)
A7: Cross-sheet reference | B7: Sheet2!A1 | C7: =Sheet2!A1
A8: Volatile function | B8: TODAY() | C8: =TODAY()
A9: Array-like range arithmetic | B9: A1:A3+B1:B3 | C9: =A1:A3+B1:B3
A10: Unsupported function | B10: VLOOKUP(1,A1:B3,2,FALSE) | C10: =VLOOKUP(1,A1:B3,2,FALSE)
A11: Cross-sheet reference | B11: Sheet2!A1 | C11: =Sheet2!A1
A12: Volatile function | B12: TODAY() | C12: =TODAY()
A13: Array-like range arithmetic | B13: A1:A3+B1:B3 | C13: =A1:A3+B1:B3
A14: Unsupported function | B14: VLOOKUP(1,A1:B3,2,FALSE) | C14: =VLOOKUP(1,A1:B3,2,FALSE)
A15: Cross-sheet reference | B15: Sheet2!A1 | C15: =Sheet2!A1
A16: Volatile function | B16: TODAY() | C16: =TODAY()
A17: Array-like range arithmetic | B17: A1:A3+B1:B3 | C17: =A1:A3+B1:B3
A18: Unsupported function | B18: VLOOKUP(1,A1:B3,2,FALSE) | C18: =VLOOKUP(1,A1:B3,2,FALSE)
A19: Cross-sheet reference | B19: Sheet2!A1 | C19: =Sheet2!A1
A20: Volatile function | B20: TODAY() | C20: =TODAY()
A21: Array-like range arithmetic | B21: A1:A3+B1:B3 | C21: =A1:A3+B1:B3
A22: Unsupported function | B22: VLOOKUP(1,A1:B3,2,FALSE) | C22: =VLOOKUP(1,A1:B3,2,FALSE)
A23: Cross-sheet reference | B23: Sheet2!A1 | C23: =Sheet2!A1
A24: Volatile function | B24: TODAY() | C24: =TODAY()
A25: Array-like range arithmetic | B25: A1:A3+B1:B3 | C25: =A1:A3+B1:B3
A26: Unsupported function | B26: VLOOKUP(1,A1:B3,2,FALSE) | C26: =VLOOKUP(1,A1:B3,2,FALSE)
A27: Cross-sheet reference | B27: Sheet2!A1 | C27: =Sheet2!A1
A28: Volatile function | B28: TODAY() | C28: =TODAY()
A29: Array-like range arithmetic | B29: A1:A3+B1:B3 | C29: =A1:A3+B1:B3
A30: Unsupported function | B30: VLOOKUP(1,A1:B3,2,FALSE) | C30: =VLOOKUP(1,A1:B3,2,FALSE)
A31: Cross-sheet reference | B31: Sheet2!A1 | C31: =Sheet2!A1
A32: Volatile function | B32: TODAY() | C32: =TODAY()
A33: Array-like range arithmetic | B33: A1:A3+B1:B3 | C33: =A1:A3+B1:B3
A34: Unsupported function | B34: VLOOKUP(1,A1:B3,2,FALSE) | C34: =VLOOKUP(1,A1:B3,2,FALSE)
A35: Cross-sheet reference | B35: Sheet2!A1 | C35: =Sheet2!A1
A36: Volatile function | B36: TODAY() | C36: =TODAY()
A37: Array-like range arithmetic | B37: A1:A3+B1:B3 | C37: =A1:A3+B1:B3
A38: Unsupported function | B38: VLOOKUP(1,A1:B3,2,FALSE) | C38: =VLOOKUP(1,A1:B3,2,FALSE)
A39: Cross-sheet reference | B39: Sheet2!A1 | C39: =Sheet2!A1
A40: Volatile function | B40: TODAY() | C40: =TODAY()
...
